Workbook

Sheet ① かんたん試算
A1: 資金計画シミュレーター 株式会社 Martial Arts
A2: 人生を、自分の土地から。 単身者向け 戸建ての資金計画（概算）
A3: 使い方：① 黄色のマスに入力する → ② 下の「結果」と「チェック」を見る → ③ もっと詳しく見るときは ②〜⑥ のタブ
A5: STEP 1 あなたのこと
A6: 項目 | B6: 入力 | E6: 入力のヒント
A7: 年収（税込） | B7: 450 | E7: 源泉徴収票の「支払金額」。万円で入力（450万円なら 450）
A8: 今の家賃（月） | B8: 65000 | E8: 管理費・共益費を含む
A9: 駐車場代（月） | B9: 5000 | E9: 車を置いていなければ 0
A10: 預貯金 | B10: 150 | E10: すぐに使える預金の合計。万円で入力
A11: 車などのローンの返済（月） | B11: 12000 | E11: なければ 0。ローン審査では住宅ローンと合わせて見られます
A13: STEP 2 住宅ローン
A14: 項目 | B14: 入力 | E14: 入力のヒント
A15: 金利（年） | B15: 0.012 | E15: 全期間この金利と仮定。変動金利なら今の金利
A16: 返済年数 | B16: 35 | E16: 35年が多い
A18: STEP 3 くらべる物件
A19: 項目 | C19: 物件A | D19: 物件B | E19: 入力のヒント
A20: 物件の名前 | C20: リフォーム済み中古戸建て | D20: 新築注文住宅 | E20: わかりやすい呼び名
A21: 物件価格 | C21: 2890 | D21: 4000 | E21: 販売価格。万円で入力
A22: 頭金 | C22: 0 | D22: 0 | E22: 0でも試算できます。万円で入力
A23: 区分 | C23: 買取再販 | D23: 新築 | E23: 新築／買取再販（リフォーム済みの中古）／中古。住宅ローン控除の判定に使う
A25: 結果（自動で計算・概算）
A26: 項目 | B26: 今の賃貸 | C26: 物件A | D26: 物件B | E26: この数字の意味
A27: 物件の名前 | B27: ="今の住まい" | C27: ='② 詳しい条件'!B33 | D27: ='② 詳しい条件'!C33
A28: 毎月の住まいの支払い | B28: ='③ 詳しい試算'!B23 | C28: ='③ 詳しい試算'!B21 | D28: ='③ 詳しい試算'!C21 | E28: ローン返済＋固定資産税・保険・修繕の積立。賃貸は家賃＋更新料・保険・駐車場の月割り
A29: うちローンの返済 | B29: — | C29: ='③ 詳しい試算'!B15 | D29: ='③ 詳しい試算'!C15 | E29: 毎月同じ額を返す方式（元利均等返済）
A30: 今の家賃との差 | B30: — | C30: ='③ 詳しい試算'!B24 | D30: ='③ 詳しい試算'!C24 | E30: ＋は今より増える、−は今より減る
A31: はじめに必要な現金 | B31: — | C31: ='③ 詳しい試算'!B16/10000 | D31: ='③ 詳しい試算'!C16/10000 | E31: 頭金＋現金で払う諸費用（諸費用もローンにするときは頭金だけ）
A32: 手元に残る預貯金 | B32: ='② 詳しい条件'!B14/10000 | C32: ='③ 詳しい試算'!B17/10000 | D32: ='③ 詳しい試算'!C17/10000 | E32: 買ったあとに残る預金
A33: 住宅ローン控除（最初の10年） | B33: — | C33: ='③ 詳しい試算'!B63/10000 | D33: ='③ 詳しい試算'!C63/10000 | E33: 税金から戻る見込み額。税額が少ないと全額は戻りません
A34: 10年間の住まいの費用 | B34: ='③ 詳しい試算'!B73/10000 | C34: ='③ 詳しい試算'!B72/10000 | D34: ='③ 詳しい試算'!C72/10000 | E34: 10年分の支払い＋はじめの現金−控除。賃貸は今の家賃が続く場合
A36: チェック（◎ 安心 △ 注意 × 要相談）
A37: チェック | B37: 基準 | C37: 物件A | D37: 物件B | E37: 見かた
A38: 返済の負担 | B38: ="◎ 年収の"&TEXT('② 詳しい条件'!B29,"0%")&"以内" | C38: =IF('③ 詳しい試算'!B30<='② 詳しい条件'!B29,"◎ 目安内",IF('③ 詳しい試算'!B30<='③ 詳しい試算'!B35,"△ やや重い","× 重い"))&"（"&TEXT('③ 詳しい試算'!B30,"0.0%")&"）" | D38: =IF('③ 詳しい試算'!C30<='② 詳しい条件'!B29,"◎ 目安内",IF('③ 詳しい試算'!C30<='③ 詳しい試算'!C35,"△ やや重い","× 重い"))&"（"&TEXT('③ 詳しい試算'!C30,"0.0%")&"）" | E38: ローン返済＋車などの返済が、年収の何%か。△は審査の基準以内だが余裕は少ない
A39: ローン審査の目安 | B39: ="審査金利"&TEXT('② 詳しい条件'!B25,"0.0%")&"で"&TEXT('③ 詳しい試算'!B35,"0%")&"以内" | C39: =IF('③ 詳しい試算'!B34<='③ 詳しい試算'!B35,"◎ 基準内","× 基準を超える")&"（"&TEXT('③ 詳しい試算'!B34,"0.0%")&"）" | D39: =IF('③ 詳しい試算'!C34<='③ 詳しい試算'!C35,"◎ 基準内","× 基準を超える")&"（"&TEXT('③ 詳しい試算'!C34,"0.0%")&"）" | E39: 金融機関は高めの金利で返済の割合を見ます。実際の審査は金融機関ごとに違います
A40: もしもの貯金 | B40: ="住まい＋生活費の6か月分" | C40: =IF('③ 詳しい試算'!B17>='③ 詳しい試算'!B25,"◎ 6か月分以上",IF('③ 詳しい試算'!B17>='③ 詳しい試算'!B25/2,"△ 3か月分以上","× 3か月分未満")) | D40: =IF('③ 詳しい試算'!C17>='③ 詳しい試算'!C25,"◎ 6か月分以上",IF('③ 詳しい試算'!C17>='③ 詳しい試算'!C25/2,"△ 3か月分以上","× 3か月分未満")) | E40: 病気や転職のときに、手元の預金で何か月暮らせるか
A41: 住宅ローン控除 | B41: ="単身者の一般の限度額で判定" | C41: =IF('③ 詳しい試算'!B56="はい","◎ 対象（"&'③ 詳しい試算'!B59&"年間）","× "&'③ 詳しい試算'!B57) | D41: =IF('③ 詳しい試算'!C56="はい","◎ 対象（"&'③ 詳しい試算'!C59&"年間）","× "&'③ 詳しい試算'!C57) | E41: ×のときは、最初に満たさない要件を表示。詳しくは ③ 詳しい試算
A43: ひとことまとめ
A44: 物件A | B44: ="「"&'② 詳しい条件'!B33&"」は、毎月 約"&TEXT('③ 詳しい試算'!B21/10000,"0.0")&"万円（今より"&IF('③ 詳しい試算'!B24>=0,"＋","−")&TEXT(ABS('③ 詳しい試算'!B24)/10000,"0.0")&"万円）。はじめに現金 "&TEXT('③ 詳しい試算'!B16/10000,"0")&"万円、住宅ローン控除は最初の10年で約"&TEXT('③ 詳しい試算'!B63/10000,"0")&"万円の見込みです。"
A45: 物件B | B45: ="「"&'② 詳しい条件'!C33&"」は、毎月 約"&TEXT('③ 詳しい試算'!C21/10000,"0.0")&"万円（今より"&IF('③ 詳しい試算'!C24>=0,"＋","−")&TEXT(ABS('③ 詳しい試算'!C24)/10000,"0.0")&"万円）。はじめに現金 "&TEXT('③ 詳しい試算'!C16/10000,"0")&"万円、住宅ローン控除は最初の10年で約"&TEXT('③ 詳しい試算'!C63/10000,"0")&"万円の見込みです。"
A47: ご注意
...

Sheet ② 詳しい条件
A1: ② 詳しい条件
A2: ふだんは変えなくてOKな既定値です。緑の文字は ① かんたん試算 で入力した値（ここでは変えられません）。
A5: お客様
A6: 項目 | B6: 値 | D6: メモ
A7: 年収（税込） | B7: ='① かんたん試算'!B7*10000 | D7: ① かんたん試算で入力
A8: 社会保険料（年収に対する割合） | B8: 0.15 | D8: 概算。源泉徴収票の社会保険料等の金額÷年収
A9: 家賃（月額） | B9: ='① かんたん試算'!B8 | D9: ① かんたん試算で入力
A10: 駐車場代（月額） | B10: ='① かんたん試算'!B9 | D10: ① かんたん試算で入力
A11: 賃貸の火災保険（年額） | B11: 15000
A12: 更新料（家賃の何か月分） | B12: 1
A13: 更新の間隔（か月） | B13: 24
A14: 預貯金 | B14: ='① かんたん試算'!B10*10000 | D14: ① かんたん試算で入力
A15: 生活費（月額・住居費を除く） | B15: 100000
A16: 他の借入の返済（月額） | B16: ='① かんたん試算'!B11 | D16: ① かんたん試算で入力
A17: 毎月の支払いの希望額 | B17: 90000 | D17: 0のときは「家賃並みで買える価格」を出さない
A18: 入居年 | B18: 2027
A19: 入居月 | B19: 3 | D19: この月に借入を実行し、翌月から返済すると仮定
A21: 住宅ローン
A22: 項目 | B22: 値 | D22: メモ
A23: 金利（年） | B23: ='① かんたん試算'!B15 | D23: ① かんたん試算で入力
A24: 返済年数 | B24: ='① かんたん試算'!B16 | D24: ① かんたん試算で入力
A25: 審査金利（年） | B25: 0.03 | D25: 金融機関が審査で使う金利の目安（仮定）
A26: 審査の返済比率の基準（年収が境目未満） | B26: 0.3 | D26: フラット35の基準。金融機関で異なる
A27: 審査の返済比率の基準（年収が境目以上） | B27: 0.35
A28: 審査基準の年収の境目 | B28: 4000000
A29: 無理のない返済の目安（年収比） | B29: 0.25 | D29: 既存の借入の返済を含む
A31: 物件
A32: 項目 | B32: 物件A | C32: 物件B | D32: メモ
A33: 名称 | B33: ='① かんたん試算'!C20 | C33: ='① かんたん試算'!D20 | D33: ① かんたん試算で入力
A34: 区分 | B34: ='① かんたん試算'!C23 | C34: ='① かんたん試算'!D23 | D34: ① かんたん試算で入力
A35: 省エネ性能 | B35: その他 | C35: ZEH水準省エネ | D35: 証明書で確認できる性能
A36: 性能の証明書がある | B36: いいえ | C36: はい | D36: ないときは「その他」として判定
A37: 物件価格 | B37: ='① かんたん試算'!C21*10000 | C37: ='① かんたん試算'!D21*10000 | D37: ① かんたん試算で入力
A38: 物件価格のうち土地の割合 | B38: 0.28373702 | C38: 0.225 | D38: 売却の目安に使う（残りが建物）
A39: うち土地 | B39: =B37*B38 | C39: =C37*C38
A40: うち建物 | B40: =B37-B39 | C40: =C37-C39
A41: 床面積（㎡） | B41: 100 | C41: 105
A42: 建築日（新築は完成予定日） | B42: 40816 | C42: 46446
A43: 建築確認日 | C43: 46235 | D43: わからなければ空欄
A44: 頭金 | B44: ='① かんたん試算'!C22*10000 | C44: ='① かんたん試算'!D22*10000 | D44: ① かんたん試算で入力
...

Sheet ③ 詳しい試算
A1: ③ 詳しい試算
A2: ① かんたん試算・② 詳しい条件 から自動で計算します（概算）。グレーの「計算用」の行は ＋ で開けます。
A5: 物件
A6: 項目 | B6: 物件A | C6: 物件B | D6: 説明
A7: 名称 | B7: ='② 詳しい条件'!B33 | C7: ='② 詳しい条件'!C33
A8: 物件価格 | B8: ='② 詳しい条件'!B37 | C8: ='② 詳しい条件'!C37
A10: 借入と初期費用
A11: 項目 | B11: 物件A | C11: 物件B | D11: 説明
A12: 諸費用 | B12: ='② 詳しい条件'!B37*'② 詳しい条件'!B45 | C12: ='② 詳しい条件'!C37*'② 詳しい条件'!C45
A13: 住宅の取得に充てる借入 | B13: =MAX(0,'② 詳しい条件'!B37-'② 詳しい条件'!B44) | C13: =MAX(0,'② 詳しい条件'!C37-'② 詳しい条件'!C44) | D13: 住宅ローン控除の対象になる部分
A14: 借入額 | B14: =B13+IF('② 詳しい条件'!B46="はい",B12,0) | C14: =C13+IF('② 詳しい条件'!C46="はい",C12,0) | D14: 諸費用もローンで借りる場合は諸費用を含む
A15: 毎月の返済額 | B15: =IF(B14<=0,0,IF('② 詳しい条件'!B23=0,B14/('② 詳しい条件'!B24*12),PMT('② 詳しい条件'!B23/12,'② 詳しい条件'!B24*12,-B14))) | C15: =IF(C14<=0,0,IF('② 詳しい条件'!B23=0,C14/('② 詳しい条件'!B24*12),PMT('② 詳しい条件'!B23/12,'② 詳しい条件'!B24*12,-C14))) | D15: 元利均等返済
A16: 初期費用（現金） | B16: ='② 詳しい条件'!B44+IF('② 詳しい条件'!B46="はい",0,B12) | C16: ='② 詳しい条件'!C44+IF('② 詳しい条件'!C46="はい",0,C12) | D16: 頭金＋現金で払う諸費用
A17: 手元に残る預貯金 | B17: ='② 詳しい条件'!B14-B16 | C17: ='② 詳しい条件'!B14-C16
A19: 毎月の住居費
A20: 項目 | B20: 物件A | C20: 物件B | D20: 説明
A21: 持ち家の住居費（月額） | B21: =B15+'② 詳しい条件'!B47/12+'② 詳しい条件'!B48/12+'② 詳しい条件'!B49 | C21: =C15+'② 詳しい条件'!C47/12+'② 詳しい条件'!C48/12+'② 詳しい条件'!C49 | D21: 返済＋税金＋保険＋修繕の積立
A22: うち返済以外 | B22: =B21-B15 | C22: =C21-C15
A23: 今の賃貸の住居費（月額） | B23: ='② 詳しい条件'!B9+'② 詳しい条件'!B9*'② 詳しい条件'!B12/'② 詳しい条件'!B13+'② 詳しい条件'!B11/12+'② 詳しい条件'!B10 | C23: ='② 詳しい条件'!B9+'② 詳しい条件'!B9*'② 詳しい条件'!B12/'② 詳しい条件'!B13+'② 詳しい条件'!B11/12+'② 詳しい条件'!B10 | D23: 家賃＋更新料の月割り＋保険＋駐車場
A24: 賃貸との差（持ち家−賃貸） | B24: =B21-B23 | C24: =C21-C23
A25: 6か月分の予備資金の目安 | B25: =(B21+'② 詳しい条件'!B15)*6 | C25: =(C21+'② 詳しい条件'!B15)*6 | D25: 住居費＋生活費の6か月分
A26: 手元資金は予備資金の目安以上か | B26: =IF(B17>=B25,"はい","不足") | C26: =IF(C17>=C25,"はい","不足")
A28: 返済の負担と審査の目安
A29: 項目 | B29: 物件A | C29: 物件B | D29: 説明
A30: 返済比率（年収比・既存の借入を含む） | B30: =IF('② 詳しい条件'!B7=0,0,(B15*12+'② 詳しい条件'!B16*12)/'② 詳しい条件'!B7) | C30: =IF('② 詳しい条件'!B7=0,0,(C15*12+'② 詳しい条件'!B16*12)/'② 詳しい条件'!B7)
A31: 無理のない返済の目安以内か | B31: =IF(B30<='② 詳しい条件'!B29,"はい","超える") | C31: =IF(C30<='② 詳しい条件'!B29,"はい","超える")
A32: 参考：手取りに対する返済の割合 | B32: =IF('参考：税額の概算'!B18=0,0,B15/'参考：税額の概算'!B18) | C32: =IF('参考：税額の概算'!B18=0,0,C15/'参考：税額の概算'!B18) | D32: 手取りは税額の概算シートの今の年収
A33: 審査金利での毎月の返済額 | B33: =IF(B14<=0,0,IF('② 詳しい条件'!B25=0,B14/('② 詳しい条件'!B24*12),PMT('② 詳しい条件'!B25/12,'② 詳しい条件'!B24*12,-B14))) | C33: =IF(C14<=0,0,IF('② 詳しい条件'!B25=0,C14/('② 詳しい条件'!B24*12),PMT('② 詳しい条件'!B25/12,'② 詳しい条件'!B24*12,-C14)))
A34: 審査の返済比率 | B34: =IF('② 詳しい条件'!B7=0,0,(B33*12+'② 詳しい条件'!B16*12)/'② 詳しい条件'!B7) | C34: =IF('② 詳しい条件'!B7=0,0,(C33*12+'② 詳しい条件'!B16*12)/'② 詳しい条件'!B7) | D34: 審査金利で計算した返済＋既存の借入
A35: 審査の基準 | B35: =IF('② 詳しい条件'!B7<'② 詳しい条件'!B28,'② 詳しい条件'!B26,'② 詳しい条件'!B27) | C35: =IF('② 詳しい条件'!B7<'② 詳しい条件'!B28,'② 詳しい条件'!B26,'② 詳しい条件'!B27)
A36: 審査の基準以内か（目安） | B36: =IF(B34<=B35,"はい","超える") | C36: =IF(C34<=C35,"はい","超える") | D36: 実際の審査は金融機関ごとに異なる
A37: 住宅ローンに使える毎月の上限（審査） | B37: =MAX(0,'② 詳しい条件'!B7*B35/12-'② 詳しい条件'!B16) | C37: =MAX(0,'② 詳しい条件'!B7*C35/12-'② 詳しい条件'!B16)
A38: 審査上の借入の上限（目安） | B38: =IF('② 詳しい条件'!B25=0,B37*'② 詳しい条件'!B24*12,PV('② 詳しい条件'!B25/12,'② 詳しい条件'!B24*12,-B37)) | C38: =IF('② 詳しい条件'!B25=0,C37*'② 詳しい条件'!B24*12,PV('② 詳しい条件'!B25/12,'② 詳しい条件'!B24*12,-C37))
A40: 住宅ローン控除の判定
A41: 項目 | B41: 物件A | C41: 物件B | D41: 説明
A42: （計算用）判定に使う省エネ性能 | B42: =IF(AND('② 詳しい条件'!B35<>"その他",'② 詳しい条件'!B36<>"はい"),"その他",'② 詳しい条件'!B35) | C42: =IF(AND('② 詳しい条件'!C35<>"その他",'② 詳しい条件'!C36<>"はい"),"その他",'② 詳しい条件'!C35) | D42: 証明書がない場合は「その他の住宅」
A43: （計算用）制度の該当行の数 | B43: =COUNTIFS('参考：控除の制度'!$A$7:$A$20,'② 詳しい条件'!B34,'参考：控除の制度'!$B$7:$B$20,B42,'参考：控除の制度'!$C$7:$C$20,"<="&'② 詳しい条件'!B18,'参考：控除の制度'!$D$7:$D$20,">="&'② 詳しい条件'!B18) | C43: =COUNTIFS('参考：控除の制度'!$A$7:$A$20,'② 詳しい条件'!C34,'参考：控除の制度'!$B$7:$B$20,C42,'参考：控除の制度'!$C$7:$C$20,"<="&'② 詳しい条件'!B18,'参考：控除の制度'!$D$7:$D$20,">="&'② 詳しい条件'!B18)
A44: （計算用）建築確認の期限（経過措置） | B44: =SUMIFS('参考：控除の制度'!$G$7:$G$20,'参考：控除の制度'!$A$7:$A$20,'② 詳しい条件'!B34,'参考：控除の制度'!$B$7:$B$20,B42,'参考：控除の制度'!$C$7:$C$20,"<="&'② 詳しい条件'!B18,'参考：控除の制度'!$D$7:$D$20,">="&'② 詳しい条件'!B18) | C44: =SUMIFS('参考：控除の制度'!$G$7:$G$20,'参考：控除の制度'!$A$7:$A$20,'② 詳しい条件'!C34,'参考：控除の制度'!$B$7:$B$20,C42,'参考：控除の制度'!$C$7:$C$20,"<="&'② 詳しい条件'!B18,'参考：控除の制度'!$D$7:$D$20,">="&'② 詳しい条件'!B18)
A45: （計算用）建築の期限（経過措置） | B45: =SUMIFS('参考：控除の制度'!$H$7:$H$20,'参考：控除の制度'!$A$7:$A$20,'② 詳しい条件'!B34,'参考：控除の制度'!$B$7:$B$20,B42,'参考：控除の制度'!$C$7:$C$20,"<="&'② 詳しい条件'!B18,'参考：控除の制度'!$D$7:$D$20,">="&'② 詳しい条件'!B18) | C45: =SUMIFS('参考：控除の制度'!$H$7:$H$20,'参考：控除の制度'!$A$7:$A$20,'② 詳しい条件'!C34,'参考：控除の制度'!$B$7:$B$20,C42,'参考：控除の制度'!$C$7:$C$20,"<="&'② 詳しい条件'!B18,'参考：控除の制度'!$D$7:$D$20,">="&'② 詳しい条件'!B18)
A46: 入居年が制度の対象（2026〜2030年） | B46: =IF(AND('② 詳しい条件'!B18>=MIN('参考：控除の制度'!$C$7:$C$20),'② 詳しい条件'!B18<=MAX('参考：控除の制度'!$D$7:$D$20)),"○","×") | C46: =IF(AND('② 詳しい条件'!B18>=MIN('参考：控除の制度'!$C$7:$C$20),'② 詳しい条件'!B18<=MAX('参考：控除の制度'!$D$7:$D$20)),"○","×")
...

Sheet ④ 住宅ローン控除
A1: ④ 住宅ローン控除の見込み（年ごと）
A2: 上限＝min（年末残高×住宅取得分の割合, 借入限度額, 物件価格）×0.7%（100円未満切捨て）。所得税→住民税の順に控除し、控除しきれない額は加算しない。
A5: 物件A | C5: ='② 詳しい条件'!B33
A6: 年目 | B6: 年 | C6: 年末残高 | D6: 控除対象の残高 | E6: 控除の上限 | F6: 所得税から | G6: 住民税から | H6: 控除しきれない額 | I6: 控除見込額
A7: 1 | B7: ='② 詳しい条件'!B18+A7-1 | C7: =IF('② 詳しい条件'!B23=0,MAX(0,'③ 詳しい試算'!B14-'③ 詳しい試算'!B15*MIN(12-'② 詳しい条件'!B19+12*(A7-1),'② 詳しい条件'!B24*12)),MAX(0,'③ 詳しい試算'!B14*(1+'② 詳しい条件'!B23/12)^MIN(12-'② 詳しい条件'!B19+12*(A7-1),'② 詳しい条件'!B24*12)-'③ 詳しい試算'!B15*((1+'② 詳しい条件'!B23/12)^MIN(12-'② 詳しい条件'!B19+12*(A7-1),'② 詳しい条件'!B24*12)-1)/('② 詳しい条件'!B23/12))) | D7: =IF('③ 詳しい試算'!B14<=0,0,C7*MIN(1,'③ 詳しい試算'!B13/'③ 詳しい試算'!B14)) | E7: =IF(AND('③ 詳しい試算'!B56="はい",A7<='③ 詳しい試算'!B59),INT(MIN(D7,'③ 詳しい試算'!B58,'② 詳しい条件'!B37)*'参考：控除の制度'!E25/100)*100,0) | F7: =MIN(E7,'参考：税額の概算'!B14) | G7: =MIN(E7-F7,MIN('参考：控除の制度'!E34,INT('参考：税額の概算'!B13*'参考：控除の制度'!E33),'参考：税額の概算'!B16)) | H7: =E7-F7-G7 | I7: =F7+G7
A8: 2 | B8: ='② 詳しい条件'!B18+A8-1 | C8: =IF('② 詳しい条件'!B23=0,MAX(0,'③ 詳しい試算'!B14-'③ 詳しい試算'!B15*MIN(12-'② 詳しい条件'!B19+12*(A8-1),'② 詳しい条件'!B24*12)),MAX(0,'③ 詳しい試算'!B14*(1+'② 詳しい条件'!B23/12)^MIN(12-'② 詳しい条件'!B19+12*(A8-1),'② 詳しい条件'!B24*12)-'③ 詳しい試算'!B15*((1+'② 詳しい条件'!B23/12)^MIN(12-'② 詳しい条件'!B19+12*(A8-1),'② 詳しい条件'!B24*12)-1)/('② 詳しい条件'!B23/12))) | D8: =IF('③ 詳しい試算'!B14<=0,0,C8*MIN(1,'③ 詳しい試算'!B13/'③ 詳しい試算'!B14)) | E8: =IF(AND('③ 詳しい試算'!B56="はい",A8<='③ 詳しい試算'!B59),INT(MIN(D8,'③ 詳しい試算'!B58,'② 詳しい条件'!B37)*'参考：控除の制度'!E25/100)*100,0) | F8: =MIN(E8,'参考：税額の概算'!B14) | G8: =MIN(E8-F8,MIN('参考：控除の制度'!E34,INT('参考：税額の概算'!B13*'参考：控除の制度'!E33),'参考：税額の概算'!B16)) | H8: =E8-F8-G8 | I8: =F8+G8
A9: 3 | B9: ='② 詳しい条件'!B18+A9-1 | C9: =IF('② 詳しい条件'!B23=0,MAX(0,'③ 詳しい試算'!B14-'③ 詳しい試算'!B15*MIN(12-'② 詳しい条件'!B19+12*(A9-1),'② 詳しい条件'!B24*12)),MAX(0,'③ 詳しい試算'!B14*(1+'② 詳しい条件'!B23/12)^MIN(12-'② 詳しい条件'!B19+12*(A9-1),'② 詳しい条件'!B24*12)-'③ 詳しい試算'!B15*((1+'② 詳しい条件'!B23/12)^MIN(12-'② 詳しい条件'!B19+12*(A9-1),'② 詳しい条件'!B24*12)-1)/('② 詳しい条件'!B23/12))) | D9: =IF('③ 詳しい試算'!B14<=0,0,C9*MIN(1,'③ 詳しい試算'!B13/'③ 詳しい試算'!B14)) | E9: =IF(AND('③ 詳しい試算'!B56="はい",A9<='③ 詳しい試算'!B59),INT(MIN(D9,'③ 詳しい試算'!B58,'② 詳しい条件'!B37)*'参考：控除の制度'!E25/100)*100,0) | F9: =MIN(E9,'参考：税額の概算'!B14) | G9: =MIN(E9-F9,MIN('参考：控除の制度'!E34,INT('参考：税額の概算'!B13*'参考：控除の制度'!E33),'参考：税額の概算'!B16)) | H9: =E9-F9-G9 | I9: =F9+G9
A10: 4 | B10: ='② 詳しい条件'!B18+A10-1 | C10: =IF('② 詳しい条件'!B23=0,MAX(0,'③ 詳しい試算'!B14-'③ 詳しい試算'!B15*MIN(12-'② 詳しい条件'!B19+12*(A10-1),'② 詳しい条件'!B24*12)),MAX(0,'③ 詳しい試算'!B14*(1+'② 詳しい条件'!B23/12)^MIN(12-'② 詳しい条件'!B19+12*(A10-1),'② 詳しい条件'!B24*12)-'③ 詳しい試算'!B15*((1+'② 詳しい条件'!B23/12)^MIN(12-'② 詳しい条件'!B19+12*(A10-1),'② 詳しい条件'!B24*12)-1)/('② 詳しい条件'!B23/12))) | D10: =IF('③ 詳しい試算'!B14<=0,0,C10*MIN(1,'③ 詳しい試算'!B13/'③ 詳しい試算'!B14)) | E10: =IF(AND('③ 詳しい試算'!B56="はい",A10<='③ 詳しい試算'!B59),INT(MIN(D10,'③ 詳しい試算'!B58,'② 詳しい条件'!B37)*'参考：控除の制度'!E25/100)*100,0) | F10: =MIN(E10,'参考：税額の概算'!B14) | G10: =MIN(E10-F10,MIN('参考：控除の制度'!E34,INT('参考：税額の概算'!B13*'参考：控除の制度'!E33),'参考：税額の概算'!B16)) | H10: =E10-F10-G10 | I10: =F10+G10
A11: 5 | B11: ='② 詳しい条件'!B18+A11-1 | C11: =IF('② 詳しい条件'!B23=0,MAX(0,'③ 詳しい試算'!B14-'③ 詳しい試算'!B15*MIN(12-'② 詳しい条件'!B19+12*(A11-1),'② 詳しい条件'!B24*12)),MAX(0,'③ 詳しい試算'!B14*(1+'② 詳しい条件'!B23/12)^MIN(12-'② 詳しい条件'!B19+12*(A11-1),'② 詳しい条件'!B24*12)-'③ 詳しい試算'!B15*((1+'② 詳しい条件'!B23/12)^MIN(12-'② 詳しい条件'!B19+12*(A11-1),'② 詳しい条件'!B24*12)-1)/('② 詳しい条件'!B23/12))) | D11: =IF('③ 詳しい試算'!B14<=0,0,C11*MIN(1,'③ 詳しい試算'!B13/'③ 詳しい試算'!B14)) | E11: =IF(AND('③ 詳しい試算'!B56="はい",A11<='③ 詳しい試算'!B59),INT(MIN(D11,'③ 詳しい試算'!B58,'② 詳しい条件'!B37)*'参考：控除の制度'!E25/100)*100,0) | F11: =MIN(E11,'参考：税額の概算'!B14) | G11: =MIN(E11-F11,MIN('参考：控除の制度'!E34,INT('参考：税額の概算'!B13*'参考：控除の制度'!E33),'参考：税額の概算'!B16)) | H11: =E11-F11-G11 | I11: =F11+G11
A12: 6 | B12: ='② 詳しい条件'!B18+A12-1 | C12: =IF('② 詳しい条件'!B23=0,MAX(0,'③ 詳しい試算'!B14-'③ 詳しい試算'!B15*MIN(12-'② 詳しい条件'!B19+12*(A12-1),'② 詳しい条件'!B24*12)),MAX(0,'③ 詳しい試算'!B14*(1+'② 詳しい条件'!B23/12)^MIN(12-'② 詳しい条件'!B19+12*(A12-1),'② 詳しい条件'!B24*12)-'③ 詳しい試算'!B15*((1+'② 詳しい条件'!B23/12)^MIN(12-'② 詳しい条件'!B19+12*(A12-1),'② 詳しい条件'!B24*12)-1)/('② 詳しい条件'!B23/12))) | D12: =IF('③ 詳しい試算'!B14<=0,0,C12*MIN(1,'③ 詳しい試算'!B13/'③ 詳しい試算'!B14)) | E12: =IF(AND('③ 詳しい試算'!B56="はい",A12<='③ 詳しい試算'!B59),INT(MIN(D12,'③ 詳しい試算'!B58,'② 詳しい条件'!B37)*'参考：控除の制度'!E25/100)*100,0) | F12: =MIN(E12,'参考：税額の概算'!B14) | G12: =MIN(E12-F12,MIN('参考：控除の制度'!E34,INT('参考：税額の概算'!B13*'参考：控除の制度'!E33),'参考：税額の概算'!B16)) | H12: =E12-F12-G12 | I12: =F12+G12
A13: 7 | B13: ='② 詳しい条件'!B18+A13-1 | C13: =IF('② 詳しい条件'!B23=0,MAX(0,'③ 詳しい試算'!B14-'③ 詳しい試算'!B15*MIN(12-'② 詳しい条件'!B19+12*(A13-1),'② 詳しい条件'!B24*12)),MAX(0,'③ 詳しい試算'!B14*(1+'② 詳しい条件'!B23/12)^MIN(12-'② 詳しい条件'!B19+12*(A13-1),'② 詳しい条件'!B24*12)-'③ 詳しい試算'!B15*((1+'② 詳しい条件'!B23/12)^MIN(12-'② 詳しい条件'!B19+12*(A13-1),'② 詳しい条件'!B24*12)-1)/('② 詳しい条件'!B23/12))) | D13: =IF('③ 詳しい試算'!B14<=0,0,C13*MIN(1,'③ 詳しい試算'!B13/'③ 詳しい試算'!B14)) | E13: =IF(AND('③ 詳しい試算'!B56="はい",A13<='③ 詳しい試算'!B59),INT(MIN(D13,'③ 詳しい試算'!B58,'② 詳しい条件'!B37)*'参考：控除の制度'!E25/100)*100,0) | F13: =MIN(E13,'参考：税額の概算'!B14) | G13: =MIN(E13-F13,MIN('参考：控除の制度'!E34,INT('参考：税額の概算'!B13*'参考：控除の制度'!E33),'参考：税額の概算'!B16)) | H13: =E13-F13-G13 | I13: =F13+G13
A14: 8 | B14: ='② 詳しい条件'!B18+A14-1 | C14: =IF('② 詳しい条件'!B23=0,MAX(0,'③ 詳しい試算'!B14-'③ 詳しい試算'!B15*MIN(12-'② 詳しい条件'!B19+12*(A14-1),'② 詳しい条件'!B24*12)),MAX(0,'③ 詳しい試算'!B14*(1+'② 詳しい条件'!B23/12)^MIN(12-'② 詳しい条件'!B19+12*(A14-1),'② 詳しい条件'!B24*12)-'③ 詳しい試算'!B15*((1+'② 詳しい条件'!B23/12)^MIN(12-'② 詳しい条件'!B19+12*(A14-1),'② 詳しい条件'!B24*12)-1)/('② 詳しい条件'!B23/12))) | D14: =IF('③ 詳しい試算'!B14<=0,0,C14*MIN(1,'③ 詳しい試算'!B13/'③ 詳しい試算'!B14)) | E14: =IF(AND('③ 詳しい試算'!B56="はい",A14<='③ 詳しい試算'!B59),INT(MIN(D14,'③ 詳しい試算'!B58,'② 詳しい条件'!B37)*'参考：控除の制度'!E25/100)*100,0) | F14: =MIN(E14,'参考：税額の概算'!B14) | G14: =MIN(E14-F14,MIN('参考：控除の制度'!E34,INT('参考：税額の概算'!B13*'参考：控除の制度'!E33),'参考：税額の概算'!B16)) | H14: =E14-F14-G14 | I14: =F14+G14
A15: 9 | B15: ='② 詳しい条件'!B18+A15-1 | C15: =IF('② 詳しい条件'!B23=0,MAX(0,'③ 詳しい試算'!B14-'③ 詳しい試算'!B15*MIN(12-'② 詳しい条件'!B19+12*(A15-1),'② 詳しい条件'!B24*12)),MAX(0,'③ 詳しい試算'!B14*(1+'② 詳しい条件'!B23/12)^MIN(12-'② 詳しい条件'!B19+12*(A15-1),'② 詳しい条件'!B24*12)-'③ 詳しい試算'!B15*((1+'② 詳しい条件'!B23/12)^MIN(12-'② 詳しい条件'!B19+12*(A15-1),'② 詳しい条件'!B24*12)-1)/('② 詳しい条件'!B23/12))) | D15: =IF('③ 詳しい試算'!B14<=0,0,C15*MIN(1,'③ 詳しい試算'!B13/'③ 詳しい試算'!B14)) | E15: =IF(AND('③ 詳しい試算'!B56="はい",A15<='③ 詳しい試算'!B59),INT(MIN(D15,'③ 詳しい試算'!B58,'② 詳しい条件'!B37)*'参考：控除の制度'!E25/100)*100,0) | F15: =MIN(E15,'参考：税額の概算'!B14) | G15: =MIN(E15-F15,MIN('参考：控除の制度'!E34,INT('参考：税額の概算'!B13*'参考：控除の制度'!E33),'参考：税額の概算'!B16)) | H15: =E15-F15-G15 | I15: =F15+G15
A16: 10 | B16: ='② 詳しい条件'!B18+A16-1 | C16: =IF('② 詳しい条件'!B23=0,MAX(0,'③ 詳しい試算'!B14-'③ 詳しい試算'!B15*MIN(12-'② 詳しい条件'!B19+12*(A16-1),'② 詳しい条件'!B24*12)),MAX(0,'③ 詳しい試算'!B14*(1+'② 詳しい条件'!B23/12)^MIN(12-'② 詳しい条件'!B19+12*(A16-1),'② 詳しい条件'!B24*12)-'③ 詳しい試算'!B15*((1+'② 詳しい条件'!B23/12)^MIN(12-'② 詳しい条件'!B19+12*(A16-1),'② 詳しい条件'!B24*12)-1)/('② 詳しい条件'!B23/12))) | D16: =IF('③ 詳しい試算'!B14<=0,0,C16*MIN(1,'③ 詳しい試算'!B13/'③ 詳しい試算'!B14)) | E16: =IF(AND('③ 詳しい試算'!B56="はい",A16<='③ 詳しい試算'!B59),INT(MIN(D16,'③ 詳しい試算'!B58,'② 詳しい条件'!B37)*'参考：控除の制度'!E25/100)*100,0) | F16: =MIN(E16,'参考：税額の概算'!B14) | G16: =MIN(E16-F16,MIN('参考：控除の制度'!E34,INT('参考：税額の概算'!B13*'参考：控除の制度'!E33),'参考：税額の概算'!B16)) | H16: =E16-F16-G16 | I16: =F16+G16
A17: 11 | B17: ='② 詳しい条件'!B18+A17-1 | C17: =IF('② 詳しい条件'!B23=0,MAX(0,'③ 詳しい試算'!B14-'③ 詳しい試算'!B15*MIN(12-'② 詳しい条件'!B19+12*(A17-1),'② 詳しい条件'!B24*12)),MAX(0,'③ 詳しい試算'!B14*(1+'② 詳しい条件'!B23/12)^MIN(12-'② 詳しい条件'!B19+12*(A17-1),'② 詳しい条件'!B24*12)-'③ 詳しい試算'!B15*((1+'② 詳しい条件'!B23/12)^MIN(12-'② 詳しい条件'!B19+12*(A17-1),'② 詳しい条件'!B24*12)-1)/('② 詳しい条件'!B23/12))) | D17: =IF('③ 詳しい試算'!B14<=0,0,C17*MIN(1,'③ 詳しい試算'!B13/'③ 詳しい試算'!B14)) | E17: =IF(AND('③ 詳しい試算'!B56="はい",A17<='③ 詳しい試算'!B59),INT(MIN(D17,'③ 詳しい試算'!B58,'② 詳しい条件'!B37)*'参考：控除の制度'!E25/100)*100,0) | F17: =MIN(E17,'参考：税額の概算'!B14) | G17: =MIN(E17-F17,MIN('参考：控除の制度'!E34,INT('参考：税額の概算'!B13*'参考：控除の制度'!E33),'参考：税額の概算'!B16)) | H17: =E17-F17-G17 | I17: =F17+G17
A18: 12 | B18: ='② 詳しい条件'!B18+A18-1 | C18: =IF('② 詳しい条件'!B23=0,MAX(0,'③ 詳しい試算'!B14-'③ 詳しい試算'!B15*MIN(12-'② 詳しい条件'!B19+12*(A18-1),'② 詳しい条件'!B24*12)),MAX(0,'③ 詳しい試算'!B14*(1+'② 詳しい条件'!B23/12)^MIN(12-'② 詳しい条件'!B19+12*(A18-1),'② 詳しい条件'!B24*12)-'③ 詳しい試算'!B15*((1+'② 詳しい条件'!B23/12)^MIN(12-'② 詳しい条件'!B19+12*(A18-1),'② 詳しい条件'!B24*12)-1)/('② 詳しい条件'!B23/12))) | D18: =IF('③ 詳しい試算'!B14<=0,0,C18*MIN(1,'③ 詳しい試算'!B13/'③ 詳しい試算'!B14)) | E18: =IF(AND('③ 詳しい試算'!B56="はい",A18<='③ 詳しい試算'!B59),INT(MIN(D18,'③ 詳しい試算'!B58,'② 詳しい条件'!B37)*'参考：控除の制度'!E25/100)*100,0) | F18: =MIN(E18,'参考：税額の概算'!B14) | G18: =MIN(E18-F18,MIN('参考：控除の制度'!E34,INT('参考：税額の概算'!B13*'参考：控除の制度'!E33),'参考：税額の概算'!B16)) | H18: =E18-F18-G18 | I18: =F18+G18
A19: 13 | B19: ='② 詳しい条件'!B18+A19-1 | C19: =IF('② 詳しい条件'!B23=0,MAX(0,'③ 詳しい試算'!B14-'③ 詳しい試算'!B15*MIN(12-'② 詳しい条件'!B19+12*(A19-1),'② 詳しい条件'!B24*12)),MAX(0,'③ 詳しい試算'!B14*(1+'② 詳しい条件'!B23/12)^MIN(12-'② 詳しい条件'!B19+12*(A19-1),'② 詳しい条件'!B24*12)-'③ 詳しい試算'!B15*((1+'② 詳しい条件'!B23/12)^MIN(12-'② 詳しい条件'!B19+12*(A19-1),'② 詳しい条件'!B24*12)-1)/('② 詳しい条件'!B23/12))) | D19: =IF('③ 詳しい試算'!B14<=0,0,C19*MIN(1,'③ 詳しい試算'!B13/'③ 詳しい試算'!B14)) | E19: =IF(AND('③ 詳しい試算'!B56="はい",A19<='③ 詳しい試算'!B59),INT(MIN(D19,'③ 詳しい試算'!B58,'② 詳しい条件'!B37)*'参考：控除の制度'!E25/100)*100,0) | F19: =MIN(E19,'参考：税額の概算'!B14) | G19: =MIN(E19-F19,MIN('参考：控除の制度'!E34,INT('参考：税額の概算'!B13*'参考：控除の制度'!E33),'参考：税額の概算'!B16)) | H19: =E19-F19-G19 | I19: =F19+G19
A20: 合計 | E20: =SUM(E7:E19) | F20: =SUM(F7:F19) | G20: =SUM(G7:G19) | H20: =SUM(H7:H19) | I20: =SUM(I7:I19)
A22: 物件B | C22: ='② 詳しい条件'!C33
A23: 年目 | B23: 年 | C23: 年末残高 | D23: 控除対象の残高 | E23: 控除の上限 | F23: 所得税から | G23: 住民税から | H23: 控除しきれない額 | I23: 控除見込額
A24: 1 | B24: ='② 詳しい条件'!B18+A24-1 | C24: =IF('② 詳しい条件'!B23=0,MAX(0,'③ 詳しい試算'!C14-'③ 詳しい試算'!C15*MIN(12-'② 詳しい条件'!B19+12*(A24-1),'② 詳しい条件'!B24*12)),MAX(0,'③ 詳しい試算'!C14*(1+'② 詳しい条件'!B23/12)^MIN(12-'② 詳しい条件'!B19+12*(A24-1),'② 詳しい条件'!B24*12)-'③ 詳しい試算'!C15*((1+'② 詳しい条件'!B23/12)^MIN(12-'② 詳しい条件'!B19+12*(A24-1),'② 詳しい条件'!B24*12)-1)/('② 詳しい条件'!B23/12))) | D24: =IF('③ 詳しい試算'!C14<=0,0,C24*MIN(1,'③ 詳しい試算'!C13/'③ 詳しい試算'!C14)) | E24: =IF(AND('③ 詳しい試算'!C56="はい",A24<='③ 詳しい試算'!C59),INT(MIN(D24,'③ 詳しい試算'!C58,'② 詳しい条件'!C37)*'参考：控除の制度'!E25/100)*100,0) | F24: =MIN(E24,'参考：税額の概算'!B14) | G24: =MIN(E24-F24,MIN('参考：控除の制度'!E34,INT('参考：税額の概算'!B13*'参考：控除の制度'!E33),'参考：税額の概算'!B16)) | H24: =E24-F24-G24 | I24: =F24+G24
A25: 2 | B25: ='② 詳しい条件'!B18+A25-1 | C25: =IF('② 詳しい条件'!B23=0,MAX(0,'③ 詳しい試算'!C14-'③ 詳しい試算'!C15*MIN(12-'② 詳しい条件'!B19+12*(A25-1),'② 詳しい条件'!B24*12)),MAX(0,'③ 詳しい試算'!C14*(1+'② 詳しい条件'!B23/12)^MIN(12-'② 詳しい条件'!B19+12*(A25-1),'② 詳しい条件'!B24*12)-'③ 詳しい試算'!C15*((1+'② 詳しい条件'!B23/12)^MIN(12-'② 詳しい条件'!B19+12*(A25-1),'② 詳しい条件'!B24*12)-1)/('② 詳しい条件'!B23/12))) | D25: =IF('③ 詳しい試算'!C14<=0,0,C25*MIN(1,'③ 詳しい試算'!C13/'③ 詳しい試算'!C14)) | E25: =IF(AND('③ 詳しい試算'!C56="はい",A25<='③ 詳しい試算'!C59),INT(MIN(D25,'③ 詳しい試算'!C58,'② 詳しい条件'!C37)*'参考：控除の制度'!E25/100)*100,0) | F25: =MIN(E25,'参考：税額の概算'!B14) | G25: =MIN(E25-F25,MIN('参考：控除の制度'!E34,INT('参考：税額の概算'!B13*'参考：控除の制度'!E33),'参考：税額の概算'!B16)) | H25: =E25-F25-G25 | I25: =F25+G25
A26: 3 | B26: ='② 詳しい条件'!B18+A26-1 | C26: =IF('② 詳しい条件'!B23=0,MAX(0,'③ 詳しい試算'!C14-'③ 詳しい試算'!C15*MIN(12-'② 詳しい条件'!B19+12*(A26-1),'② 詳しい条件'!B24*12)),MAX(0,'③ 詳しい試算'!C14*(1+'② 詳しい条件'!B23/12)^MIN(12-'② 詳しい条件'!B19+12*(A26-1),'② 詳しい条件'!B24*12)-'③ 詳しい試算'!C15*((1+'② 詳しい条件'!B23/12)^MIN(12-'② 詳しい条件'!B19+12*(A26-1),'② 詳しい条件'!B24*12)-1)/('② 詳しい条件'!B23/12))) | D26: =IF('③ 詳しい試算'!C14<=0,0,C26*MIN(1,'③ 詳しい試算'!C13/'③ 詳しい試算'!C14)) | E26: =IF(AND('③ 詳しい試算'!C56="はい",A26<='③ 詳しい試算'!C59),INT(MIN(D26,'③ 詳しい試算'!C58,'② 詳しい条件'!C37)*'参考：控除の制度'!E25/100)*100,0) | F26: =MIN(E26,'参考：税額の概算'!B14) | G26: =MIN(E26-F26,MIN('参考：控除の制度'!E34,INT('参考：税額の概算'!B13*'参考：控除の制度'!E33),'参考：税額の概算'!B16)) | H26: =E26-F26-G26 | I26: =F26+G26
A27: 4 | B27: ='② 詳しい条件'!B18+A27-1 | C27: =IF('② 詳しい条件'!B23=0,MAX(0,'③ 詳しい試算'!C14-'③ 詳しい試算'!C15*MIN(12-'② 詳しい条件'!B19+12*(A27-1),'② 詳しい条件'!B24*12)),MAX(0,'③ 詳しい試算'!C14*(1+'② 詳しい条件'!B23/12)^MIN(12-'② 詳しい条件'!B19+12*(A27-1),'② 詳しい条件'!B24*12)-'③ 詳しい試算'!C15*((1+'② 詳しい条件'!B23/12)^MIN(12-'② 詳しい条件'!B19+12*(A27-1),'② 詳しい条件'!B24*12)-1)/('② 詳しい条件'!B23/12))) | D27: =IF('③ 詳しい試算'!C14<=0,0,C27*MIN(1,'③ 詳しい試算'!C13/'③ 詳しい試算'!C14)) | E27: =IF(AND('③ 詳しい試算'!C56="はい",A27<='③ 詳しい試算'!C59),INT(MIN(D27,'③ 詳しい試算'!C58,'② 詳しい条件'!C37)*'参考：控除の制度'!E25/100)*100,0) | F27: =MIN(E27,'参考：税額の概算'!B14) | G27: =MIN(E27-F27,MIN('参考：控除の制度'!E34,INT('参考：税額の概算'!B13*'参考：控除の制度'!E33),'参考：税額の概算'!B16)) | H27: =E27-F27-G27 | I27: =F27+G27
A28: 5 | B28: ='② 詳しい条件'!B18+A28-1 | C28: =IF('② 詳しい条件'!B23=0,MAX(0,'③ 詳しい試算'!C14-'③ 詳しい試算'!C15*MIN(12-'② 詳しい条件'!B19+12*(A28-1),'② 詳しい条件'!B24*12)),MAX(0,'③ 詳しい試算'!C14*(1+'② 詳しい条件'!B23/12)^MIN(12-'② 詳しい条件'!B19+12*(A28-1),'② 詳しい条件'!B24*12)-'③ 詳しい試算'!C15*((1+'② 詳しい条件'!B23/12)^MIN(12-'② 詳しい条件'!B19+12*(A28-1),'② 詳しい条件'!B24*12)-1)/('② 詳しい条件'!B23/12))) | D28: =IF('③ 詳しい試算'!C14<=0,0,C28*MIN(1,'③ 詳しい試算'!C13/'③ 詳しい試算'!C14)) | E28: =IF(AND('③ 詳しい試算'!C56="はい",A28<='③ 詳しい試算'!C59),INT(MIN(D28,'③ 詳しい試算'!C58,'② 詳しい条件'!C37)*'参考：控除の制度'!E25/100)*100,0) | F28: =MIN(E28,'参考：税額の概算'!B14) | G28: =MIN(E28-F28,MIN('参考：控除の制度'!E34,INT('参考：税額の概算'!B13*'参考：控除の制度'!E33),'参考：税額の概算'!B16)) | H28: =E28-F28-G28 | I28: =F28+G28
A29: 6 | B29: ='② 詳しい条件'!B18+A29-1 | C29: =IF('② 詳しい条件'!B23=0,MAX(0,'③ 詳しい試算'!C14-'③ 詳しい試算'!C15*MIN(12-'② 詳しい条件'!B19+12*(A29-1),'② 詳しい条件'!B24*12)),MAX(0,'③ 詳しい試算'!C14*(1+'② 詳しい条件'!B23/12)^MIN(12-'② 詳しい条件'!B19+12*(A29-1),'② 詳しい条件'!B24*12)-'③ 詳しい試算'!C15*((1+'② 詳しい条件'!B23/12)^MIN(12-'② 詳しい条件'!B19+12*(A29-1),'② 詳しい条件'!B24*12)-1)/('② 詳しい条件'!B23/12))) | D29: =IF('③ 詳しい試算'!C14<=0,0,C29*MIN(1,'③ 詳しい試算'!C13/'③ 詳しい試算'!C14)) | E29: =IF(AND('③ 詳しい試算'!C56="はい",A29<='③ 詳しい試算'!C59),INT(MIN(D29,'③ 詳しい試算'!C58,'② 詳しい条件'!C37)*'参考：控除の制度'!E25/100)*100,0) | F29: =MIN(E29,'参考：税額の概算'!B14) | G29: =MIN(E29-F29,MIN('参考：控除の制度'!E34,INT('参考：税額の概算'!B13*'参考：控除の制度'!E33),'参考：税額の概算'!B16)) | H29: =E29-F29-G29 | I29: =F29+G29
A30: 7 | B30: ='② 詳しい条件'!B18+A30-1 | C30: =IF('② 詳しい条件'!B23=0,MAX(0,'③ 詳しい試算'!C14-'③ 詳しい試算'!C15*MIN(12-'② 詳しい条件'!B19+12*(A30-1),'② 詳しい条件'!B24*12)),MAX(0,'③ 詳しい試算'!C14*(1+'② 詳しい条件'!B23/12)^MIN(12-'② 詳しい条件'!B19+12*(A30-1),'② 詳しい条件'!B24*12)-'③ 詳しい試算'!C15*((1+'② 詳しい条件'!B23/12)^MIN(12-'② 詳しい条件'!B19+12*(A30-1),'② 詳しい条件'!B24*12)-1)/('② 詳しい条件'!B23/12))) | D30: =IF('③ 詳しい試算'!C14<=0,0,C30*MIN(1,'③ 詳しい試算'!C13/'③ 詳しい試算'!C14)) | E30: =IF(AND('③ 詳しい試算'!C56="はい",A30<='③ 詳しい試算'!C59),INT(MIN(D30,'③ 詳しい試算'!C58,'② 詳しい条件'!C37)*'参考：控除の制度'!E25/100)*100,0) | F30: =MIN(E30,'参考：税額の概算'!B14) | G30: =MIN(E30-F30,MIN('参考：控除の制度'!E34,INT('参考：税額の概算'!B13*'参考：控除の制度'!E33),'参考：税額の概算'!B16)) | H30: =E30-F30-G30 | I30: =F30+G30
A31: 8 | B31: ='② 詳しい条件'!B18+A31-1 | C31: =IF('② 詳しい条件'!B23=0,MAX(0,'③ 詳しい試算'!C14-'③ 詳しい試算'!C15*MIN(12-'② 詳しい条件'!B19+12*(A31-1),'② 詳しい条件'!B24*12)),MAX(0,'③ 詳しい試算'!C14*(1+'② 詳しい条件'!B23/12)^MIN(12-'② 詳しい条件'!B19+12*(A31-1),'② 詳しい条件'!B24*12)-'③ 詳しい試算'!C15*((1+'② 詳しい条件'!B23/12)^MIN(12-'② 詳しい条件'!B19+12*(A31-1),'② 詳しい条件'!B24*12)-1)/('② 詳しい条件'!B23/12))) | D31: =IF('③ 詳しい試算'!C14<=0,0,C31*MIN(1,'③ 詳しい試算'!C13/'③ 詳しい試算'!C14)) | E31: =IF(AND('③ 詳しい試算'!C56="はい",A31<='③ 詳しい試算'!C59),INT(MIN(D31,'③ 詳しい試算'!C58,'② 詳しい条件'!C37)*'参考：控除の制度'!E25/100)*100,0) | F31: =MIN(E31,'参考：税額の概算'!B14) | G31: =MIN(E31-F31,MIN('参考：控除の制度'!E34,INT('参考：税額の概算'!B13*'参考：控除の制度'!E33),'参考：税額の概算'!B16)) | H31: =E31-F31-G31 | I31: =F31+G31
A32: 9 | B32: ='② 詳しい条件'!B18+A32-1 | C32: =IF('② 詳しい条件'!B23=0,MAX(0,'③ 詳しい試算'!C14-'③ 詳しい試算'!C15*MIN(12-'② 詳しい条件'!B19+12*(A32-1),'② 詳しい条件'!B24*12)),MAX(0,'③ 詳しい試算'!C14*(1+'② 詳しい条件'!B23/12)^MIN(12-'② 詳しい条件'!B19+12*(A32-1),'② 詳しい条件'!B24*12)-'③ 詳しい試算'!C15*((1+'② 詳しい条件'!B23/12)^MIN(12-'② 詳しい条件'!B19+12*(A32-1),'② 詳しい条件'!B24*12)-1)/('② 詳しい条件'!B23/12))) | D32: =IF('③ 詳しい試算'!C14<=0,0,C32*MIN(1,'③ 詳しい試算'!C13/'③ 詳しい試算'!C14)) | E32: =IF(AND('③ 詳しい試算'!C56="はい",A32<='③ 詳しい試算'!C59),INT(MIN(D32,'③ 詳しい試算'!C58,'② 詳しい条件'!C37)*'参考：控除の制度'!E25/100)*100,0) | F32: =MIN(E32,'参考：税額の概算'!B14) | G32: =MIN(E32-F32,MIN('参考：控除の制度'!E34,INT('参考：税額の概算'!B13*'参考：控除の制度'!E33),'参考：税額の概算'!B16)) | H32: =E32-F32-G32 | I32: =F32+G32
A33: 10 | B33: ='② 詳しい条件'!B18+A33-1 | C33: =IF('② 詳しい条件'!B23=0,MAX(0,'③ 詳しい試算'!C14-'③ 詳しい試算'!C15*MIN(12-'② 詳しい条件'!B19+12*(A33-1),'② 詳しい条件'!B24*12)),MAX(0,'③ 詳しい試算'!C14*(1+'② 詳しい条件'!B23/12)^MIN(12-'② 詳しい条件'!B19+12*(A33-1),'② 詳しい条件'!B24*12)-'③ 詳しい試算'!C15*((1+'② 詳しい条件'!B23/12)^MIN(12-'② 詳しい条件'!B19+12*(A33-1),'② 詳しい条件'!B24*12)-1)/('② 詳しい条件'!B23/12))) | D33: =IF('③ 詳しい試算'!C14<=0,0,C33*MIN(1,'③ 詳しい試算'!C13/'③ 詳しい試算'!C14)) | E33: =IF(AND('③ 詳しい試算'!C56="はい",A33<='③ 詳しい試算'!C59),INT(MIN(D33,'③ 詳しい試算'!C58,'② 詳しい条件'!C37)*'参考：控除の制度'!E25/100)*100,0) | F33: =MIN(E33,'参考：税額の概算'!B14) | G33: =MIN(E33-F33,MIN('参考：控除の制度'!E34,INT('参考：税額の概算'!B13*'参考：控除の制度'!E33),'参考：税額の概算'!B16)) | H33: =E33-F33-G33 | I33: =F33+G33
A34: 11 | B34: ='② 詳しい条件'!B18+A34-1 | C34: =IF('② 詳しい条件'!B23=0,MAX(0,'③ 詳しい試算'!C14-'③ 詳しい試算'!C15*MIN(12-'② 詳しい条件'!B19+12*(A34-1),'② 詳しい条件'!B24*12)),MAX(0,'③ 詳しい試算'!C14*(1+'② 詳しい条件'!B23/12)^MIN(12-'② 詳しい条件'!B19+12*(A34-1),'② 詳しい条件'!B24*12)-'③ 詳しい試算'!C15*((1+'② 詳しい条件'!B23/12)^MIN(12-'② 詳しい条件'!B19+12*(A34-1),'② 詳しい条件'!B24*12)-1)/('② 詳しい条件'!B23/12))) | D34: =IF('③ 詳しい試算'!C14<=0,0,C34*MIN(1,'③ 詳しい試算'!C13/'③ 詳しい試算'!C14)) | E34: =IF(AND('③ 詳しい試算'!C56="はい",A34<='③ 詳しい試算'!C59),INT(MIN(D34,'③ 詳しい試算'!C58,'② 詳しい条件'!C37)*'参考：控除の制度'!E25/100)*100,0) | F34: =MIN(E34,'参考：税額の概算'!B14) | G34: =MIN(E34-F34,MIN('参考：控除の制度'!E34,INT('参考：税額の概算'!B13*'参考：控除の制度'!E33),'参考：税額の概算'!B16)) | H34: =E34-F34-G34 | I34: =F34+G34
A35: 12 | B35: ='② 詳しい条件'!B18+A35-1 | C35: =IF('② 詳しい条件'!B23=0,MAX(0,'③ 詳しい試算'!C14-'③ 詳しい試算'!C15*MIN(12-'② 詳しい条件'!B19+12*(A35-1),'② 詳しい条件'!B24*12)),MAX(0,'③ 詳しい試算'!C14*(1+'② 詳しい条件'!B23/12)^MIN(12-'② 詳しい条件'!B19+12*(A35-1),'② 詳しい条件'!B24*12)-'③ 詳しい試算'!C15*((1+'② 詳しい条件'!B23/12)^MIN(12-'② 詳しい条件'!B19+12*(A35-1),'② 詳しい条件'!B24*12)-1)/('② 詳しい条件'!B23/12))) | D35: =IF('③ 詳しい試算'!C14<=0,0,C35*MIN(1,'③ 詳しい試算'!C13/'③ 詳しい試算'!C14)) | E35: =IF(AND('③ 詳しい試算'!C56="はい",A35<='③ 詳しい試算'!C59),INT(MIN(D35,'③ 詳しい試算'!C58,'② 詳しい条件'!C37)*'参考：控除の制度'!E25/100)*100,0) | F35: =MIN(E35,'参考：税額の概算'!B14) | G35: =MIN(E35-F35,MIN('参考：控除の制度'!E34,INT('参考：税額の概算'!B13*'参考：控除の制度'!E33),'参考：税額の概算'!B16)) | H35: =E35-F35-G35 | I35: =F35+G35
A36: 13 | B36: ='② 詳しい条件'!B18+A36-1 | C36: =IF('② 詳しい条件'!B23=0,MAX(0,'③ 詳しい試算'!C14-'③ 詳しい試算'!C15*MIN(12-'② 詳しい条件'!B19+12*(A36-1),'② 詳しい条件'!B24*12)),MAX(0,'③ 詳しい試算'!C14*(1+'② 詳しい条件'!B23/12)^MIN(12-'② 詳しい条件'!B19+12*(A36-1),'② 詳しい条件'!B24*12)-'③ 詳しい試算'!C15*((1+'② 詳しい条件'!B23/12)^MIN(12-'② 詳しい条件'!B19+12*(A36-1),'② 詳しい条件'!B24*12)-1)/('② 詳しい条件'!B23/12))) | D36: =IF('③ 詳しい試算'!C14<=0,0,C36*MIN(1,'③ 詳しい試算'!C13/'③ 詳しい試算'!C14)) | E36: =IF(AND('③ 詳しい試算'!C56="はい",A36<='③ 詳しい試算'!C59),INT(MIN(D36,'③ 詳しい試算'!C58,'② 詳しい条件'!C37)*'参考：控除の制度'!E25/100)*100,0) | F36: =MIN(E36,'参考：税額の概算'!B14) | G36: =MIN(E36-F36,MIN('参考：控除の制度'!E34,INT('参考：税額の概算'!B13*'参考：控除の制度'!E33),'参考：税額の概算'!B16)) | H36: =E36-F36-G36 | I36: =F36+G36
A37: 合計 | E37: =SUM(E24:E36) | F37: =SUM(F24:F36) | G37: =SUM(G24:G36) | H37: =SUM(H24:H36) | I37: =SUM(I24:I36)

Sheet ⑤ 収入が減ったら
A1: ⑤ 収入が減ったら
A2: 年収が下がった場合の毎月の手取りと、住居費・生活費・他の借入の返済を比べます（税額は概算）。
A5: 物件A | B5: ='② 詳しい条件'!B33
A6: 項目 | B6: 今の年収 | C6: 2割減 | D6: 4割減 | E6: 説明
A7: 年収 | B7: ='参考：税額の概算'!B8 | C7: ='参考：税額の概算'!C8 | D7: ='参考：税額の概算'!D8
A8: 手取り（月額・概算） | B8: ='参考：税額の概算'!B18 | C8: ='参考：税額の概算'!C18 | D8: ='参考：税額の概算'!D18
A9: 返済÷手取り | B9: =IF('参考：税額の概算'!B18=0,0,'③ 詳しい試算'!B15/'参考：税額の概算'!B18) | C9: =IF('参考：税額の概算'!C18=0,0,'③ 詳しい試算'!B15/'参考：税額の概算'!C18) | D9: =IF('参考：税額の概算'!D18=0,0,'③ 詳しい試算'!B15/'参考：税額の概算'!D18)
A10: 住居費÷手取り | B10: =IF('参考：税額の概算'!B18=0,0,'③ 詳しい試算'!B21/'参考：税額の概算'!B18) | C10: =IF('参考：税額の概算'!C18=0,0,'③ 詳しい試算'!B21/'参考：税額の概算'!C18) | D10: =IF('参考：税額の概算'!D18=0,0,'③ 詳しい試算'!B21/'参考：税額の概算'!D18)
A11: 毎月の過不足 | B11: ='参考：税額の概算'!B18-('③ 詳しい試算'!B21+'② 詳しい条件'!B15+'② 詳しい条件'!B16) | C11: ='参考：税額の概算'!C18-('③ 詳しい試算'!B21+'② 詳しい条件'!B15+'② 詳しい条件'!B16) | D11: ='参考：税額の概算'!D18-('③ 詳しい試算'!B21+'② 詳しい条件'!B15+'② 詳しい条件'!B16) | E11: 手取り−（住居費＋生活費＋他の借入の返済）
A12: 預貯金で補える月数 | B12: =IF(B11>=0,"不足なし",MAX(0,'③ 詳しい試算'!B17)/-B11) | C12: =IF(C11>=0,"不足なし",MAX(0,'③ 詳しい試算'!B17)/-C11) | D12: =IF(D11>=0,"不足なし",MAX(0,'③ 詳しい試算'!B17)/-D11) | E12: マイナスのとき、手元に残る預貯金で何か月補えるか
A14: 物件B | B14: ='② 詳しい条件'!C33
A15: 項目 | B15: 今の年収 | C15: 2割減 | D15: 4割減 | E15: 説明
A16: 年収 | B16: ='参考：税額の概算'!B8 | C16: ='参考：税額の概算'!C8 | D16: ='参考：税額の概算'!D8
A17: 手取り（月額・概算） | B17: ='参考：税額の概算'!B18 | C17: ='参考：税額の概算'!C18 | D17: ='参考：税額の概算'!D18
A18: 返済÷手取り | B18: =IF('参考：税額の概算'!B18=0,0,'③ 詳しい試算'!C15/'参考：税額の概算'!B18) | C18: =IF('参考：税額の概算'!C18=0,0,'③ 詳しい試算'!C15/'参考：税額の概算'!C18) | D18: =IF('参考：税額の概算'!D18=0,0,'③ 詳しい試算'!C15/'参考：税額の概算'!D18)
A19: 住居費÷手取り | B19: =IF('参考：税額の概算'!B18=0,0,'③ 詳しい試算'!C21/'参考：税額の概算'!B18) | C19: =IF('参考：税額の概算'!C18=0,0,'③ 詳しい試算'!C21/'参考：税額の概算'!C18) | D19: =IF('参考：税額の概算'!D18=0,0,'③ 詳しい試算'!C21/'参考：税額の概算'!D18)
A20: 毎月の過不足 | B20: ='参考：税額の概算'!B18-('③ 詳しい試算'!C21+'② 詳しい条件'!B15+'② 詳しい条件'!B16) | C20: ='参考：税額の概算'!C18-('③ 詳しい試算'!C21+'② 詳しい条件'!B15+'② 詳しい条件'!B16) | D20: ='参考：税額の概算'!D18-('③ 詳しい試算'!C21+'② 詳しい条件'!B15+'② 詳しい条件'!B16) | E20: 手取り−（住居費＋生活費＋他の借入の返済）
A21: 預貯金で補える月数 | B21: =IF(B20>=0,"不足なし",MAX(0,'③ 詳しい試算'!C17)/-B20) | C21: =IF(C20>=0,"不足なし",MAX(0,'③ 詳しい試算'!C17)/-C20) | D21: =IF(D20>=0,"不足なし",MAX(0,'③ 詳しい試算'!C17)/-D20) | E21: マイナスのとき、手元に残る預貯金で何か月補えるか

Sheet ⑥ 売却の目安
A1: ⑥ 売却の目安（シナリオ）
A2: 土地は毎年一定の割合で変化、建物は10年後に ② 詳しい条件 の割合になる直線で減価（下限は今の1割）と仮定。将来の価格を約束するものではありません。
A5: シナリオの前提
A6: 項目 | B6: 下落 | C6: 横ばい | D6: 上昇 | E6: メモ
A7: 地価の変化（年） | B7: -0.01 | C7: 0 | D7: 0.01
A8: 10年後の建物価値の増減（入力値に対して） | B8: -0.1 | C8: 0 | D8: 0.1
A9: 建物価値の下限（今の価値に対する割合） | B9: 0.1
A10: 仲介手数料以外の売却費用 | B10: 100000 | E10: 登記・書類など（仮定）
A11: 仲介手数料の消費税 | B11: 0.1 | E11: 仲介手数料は宅地建物取引業法の上限で計算
A13: 物件A・5年後に売る場合 | B13: ='② 詳しい条件'!B33
A14: 項目 | B14: 下落 | C14: 横ばい | D14: 上昇 | E14: 説明
A15: 土地の価値 | B15: ='② 詳しい条件'!B39*(1+B7)^5 | C15: ='② 詳しい条件'!B39*(1+C7)^5 | D15: ='② 詳しい条件'!B39*(1+D7)^5
A16: 建物の価値 | B16: ='② 詳しい条件'!B40*MAX(B9,1-(1-MIN(0.95,MAX(0.05,'② 詳しい条件'!B50+B8)))/10*5) | C16: ='② 詳しい条件'!B40*MAX(B9,1-(1-MIN(0.95,MAX(0.05,'② 詳しい条件'!B50+C8)))/10*5) | D16: ='② 詳しい条件'!B40*MAX(B9,1-(1-MIN(0.95,MAX(0.05,'② 詳しい条件'!B50+D8)))/10*5)
A17: 売却価格の目安 | B17: =B15+B16 | C17: =C15+C16 | D17: =D15+D16
A18: 売却の費用 | B18: =IF(B17<=2000000,B17*0.05,IF(B17<=4000000,B17*0.04+20000,B17*0.03+60000))*(1+B11)+B10 | C18: =IF(C17<=2000000,C17*0.05,IF(C17<=4000000,C17*0.04+20000,C17*0.03+60000))*(1+B11)+B10 | D18: =IF(D17<=2000000,D17*0.05,IF(D17<=4000000,D17*0.04+20000,D17*0.03+60000))*(1+B11)+B10 | E18: 仲介手数料（上限）＋その他
A19: ローン残高 | B19: =IF('② 詳しい条件'!B23=0,MAX(0,'③ 詳しい試算'!B14-'③ 詳しい試算'!B15*MIN(5*12,'② 詳しい条件'!B24*12)),MAX(0,'③ 詳しい試算'!B14*(1+'② 詳しい条件'!B23/12)^MIN(5*12,'② 詳しい条件'!B24*12)-'③ 詳しい試算'!B15*((1+'② 詳しい条件'!B23/12)^MIN(5*12,'② 詳しい条件'!B24*12)-1)/('② 詳しい条件'!B23/12))) | C19: =IF('② 詳しい条件'!B23=0,MAX(0,'③ 詳しい試算'!B14-'③ 詳しい試算'!B15*MIN(5*12,'② 詳しい条件'!B24*12)),MAX(0,'③ 詳しい試算'!B14*(1+'② 詳しい条件'!B23/12)^MIN(5*12,'② 詳しい条件'!B24*12)-'③ 詳しい試算'!B15*((1+'② 詳しい条件'!B23/12)^MIN(5*12,'② 詳しい条件'!B24*12)-1)/('② 詳しい条件'!B23/12))) | D19: =IF('② 詳しい条件'!B23=0,MAX(0,'③ 詳しい試算'!B14-'③ 詳しい試算'!B15*MIN(5*12,'② 詳しい条件'!B24*12)),MAX(0,'③ 詳しい試算'!B14*(1+'② 詳しい条件'!B23/12)^MIN(5*12,'② 詳しい条件'!B24*12)-'③ 詳しい試算'!B15*((1+'② 詳しい条件'!B23/12)^MIN(5*12,'② 詳しい条件'!B24*12)-1)/('② 詳しい条件'!B23/12)))
A20: 手元に残る額（マイナスは不足） | B20: =B17-B18-B19 | C20: =C17-C18-C19 | D20: =D17-D18-D19 | E20: 売却価格−費用−ローン残高
A22: 物件A・10年後に売る場合 | B22: ='② 詳しい条件'!B33
A23: 項目 | B23: 下落 | C23: 横ばい | D23: 上昇 | E23: 説明
A24: 土地の価値 | B24: ='② 詳しい条件'!B39*(1+B7)^10 | C24: ='② 詳しい条件'!B39*(1+C7)^10 | D24: ='② 詳しい条件'!B39*(1+D7)^10
A25: 建物の価値 | B25: ='② 詳しい条件'!B40*MAX(B9,1-(1-MIN(0.95,MAX(0.05,'② 詳しい条件'!B50+B8)))/10*10) | C25: ='② 詳しい条件'!B40*MAX(B9,1-(1-MIN(0.95,MAX(0.05,'② 詳しい条件'!B50+C8)))/10*10) | D25: ='② 詳しい条件'!B40*MAX(B9,1-(1-MIN(0.95,MAX(0.05,'② 詳しい条件'!B50+D8)))/10*10)
A26: 売却価格の目安 | B26: =B24+B25 | C26: =C24+C25 | D26: =D24+D25
A27: 売却の費用 | B27: =IF(B26<=2000000,B26*0.05,IF(B26<=4000000,B26*0.04+20000,B26*0.03+60000))*(1+B11)+B10 | C27: =IF(C26<=2000000,C26*0.05,IF(C26<=4000000,C26*0.04+20000,C26*0.03+60000))*(1+B11)+B10 | D27: =IF(D26<=2000000,D26*0.05,IF(D26<=4000000,D26*0.04+20000,D26*0.03+60000))*(1+B11)+B10 | E27: 仲介手数料（上限）＋その他
A28: ローン残高 | B28: =IF('② 詳しい条件'!B23=0,MAX(0,'③ 詳しい試算'!B14-'③ 詳しい試算'!B15*MIN(10*12,'② 詳しい条件'!B24*12)),MAX(0,'③ 詳しい試算'!B14*(1+'② 詳しい条件'!B23/12)^MIN(10*12,'② 詳しい条件'!B24*12)-'③ 詳しい試算'!B15*((1+'② 詳しい条件'!B23/12)^MIN(10*12,'② 詳しい条件'!B24*12)-1)/('② 詳しい条件'!B23/12))) | C28: =IF('② 詳しい条件'!B23=0,MAX(0,'③ 詳しい試算'!B14-'③ 詳しい試算'!B15*MIN(10*12,'② 詳しい条件'!B24*12)),MAX(0,'③ 詳しい試算'!B14*(1+'② 詳しい条件'!B23/12)^MIN(10*12,'② 詳しい条件'!B24*12)-'③ 詳しい試算'!B15*((1+'② 詳しい条件'!B23/12)^MIN(10*12,'② 詳しい条件'!B24*12)-1)/('② 詳しい条件'!B23/12))) | D28: =IF('② 詳しい条件'!B23=0,MAX(0,'③ 詳しい試算'!B14-'③ 詳しい試算'!B15*MIN(10*12,'② 詳しい条件'!B24*12)),MAX(0,'③ 詳しい試算'!B14*(1+'② 詳しい条件'!B23/12)^MIN(10*12,'② 詳しい条件'!B24*12)-'③ 詳しい試算'!B15*((1+'② 詳しい条件'!B23/12)^MIN(10*12,'② 詳しい条件'!B24*12)-1)/('② 詳しい条件'!B23/12)))
A29: 手元に残る額（マイナスは不足） | B29: =B26-B27-B28 | C29: =C26-C27-C28 | D29: =D26-D27-D28 | E29: 売却価格−費用−ローン残高
A31: 物件A・20年後に売る場合 | B31: ='② 詳しい条件'!B33
A32: 項目 | B32: 下落 | C32: 横ばい | D32: 上昇 | E32: 説明
A33: 土地の価値 | B33: ='② 詳しい条件'!B39*(1+B7)^20 | C33: ='② 詳しい条件'!B39*(1+C7)^20 | D33: ='② 詳しい条件'!B39*(1+D7)^20
A34: 建物の価値 | B34: ='② 詳しい条件'!B40*MAX(B9,1-(1-MIN(0.95,MAX(0.05,'② 詳しい条件'!B50+B8)))/10*20) | C34: ='② 詳しい条件'!B40*MAX(B9,1-(1-MIN(0.95,MAX(0.05,'② 詳しい条件'!B50+C8)))/10*20) | D34: ='② 詳しい条件'!B40*MAX(B9,1-(1-MIN(0.95,MAX(0.05,'② 詳しい条件'!B50+D8)))/10*20)
A35: 売却価格の目安 | B35: =B33+B34 | C35: =C33+C34 | D35: =D33+D34
A36: 売却の費用 | B36: =IF(B35<=2000000,B35*0.05,IF(B35<=4000000,B35*0.04+20000,B35*0.03+60000))*(1+B11)+B10 | C36: =IF(C35<=2000000,C35*0.05,IF(C35<=4000000,C35*0.04+20000,C35*0.03+60000))*(1+B11)+B10 | D36: =IF(D35<=2000000,D35*0.05,IF(D35<=4000000,D35*0.04+20000,D35*0.03+60000))*(1+B11)+B10 | E36: 仲介手数料（上限）＋その他
A37: ローン残高 | B37: =IF('② 詳しい条件'!B23=0,MAX(0,'③ 詳しい試算'!B14-'③ 詳しい試算'!B15*MIN(20*12,'② 詳しい条件'!B24*12)),MAX(0,'③ 詳しい試算'!B14*(1+'② 詳しい条件'!B23/12)^MIN(20*12,'② 詳しい条件'!B24*12)-'③ 詳しい試算'!B15*((1+'② 詳しい条件'!B23/12)^MIN(20*12,'② 詳しい条件'!B24*12)-1)/('② 詳しい条件'!B23/12))) | C37: =IF('② 詳しい条件'!B23=0,MAX(0,'③ 詳しい試算'!B14-'③ 詳しい試算'!B15*MIN(20*12,'② 詳しい条件'!B24*12)),MAX(0,'③ 詳しい試算'!B14*(1+'② 詳しい条件'!B23/12)^MIN(20*12,'② 詳しい条件'!B24*12)-'③ 詳しい試算'!B15*((1+'② 詳しい条件'!B23/12)^MIN(20*12,'② 詳しい条件'!B24*12)-1)/('② 詳しい条件'!B23/12))) | D37: =IF('② 詳しい条件'!B23=0,MAX(0,'③ 詳しい試算'!B14-'③ 詳しい試算'!B15*MIN(20*12,'② 詳しい条件'!B24*12)),MAX(0,'③ 詳しい試算'!B14*(1+'② 詳しい条件'!B23/12)^MIN(20*12,'② 詳しい条件'!B24*12)-'③ 詳しい試算'!B15*((1+'② 詳しい条件'!B23/12)^MIN(20*12,'② 詳しい条件'!B24*12)-1)/('② 詳しい条件'!B23/12)))
A38: 手元に残る額（マイナスは不足） | B38: =B35-B36-B37 | C38: =C35-C36-C37 | D38: =D35-D36-D37 | E38: 売却価格−費用−ローン残高
A40: 物件B・5年後に売る場合 | B40: ='② 詳しい条件'!C33
A41: 項目 | B41: 下落 | C41: 横ばい | D41: 上昇 | E41: 説明
A42: 土地の価値 | B42: ='② 詳しい条件'!C39*(1+B7)^5 | C42: ='② 詳しい条件'!C39*(1+C7)^5 | D42: ='② 詳しい条件'!C39*(1+D7)^5
A43: 建物の価値 | B43: ='② 詳しい条件'!C40*MAX(B9,1-(1-MIN(0.95,MAX(0.05,'② 詳しい条件'!C50+B8)))/10*5) | C43: ='② 詳しい条件'!C40*MAX(B9,1-(1-MIN(0.95,MAX(0.05,'② 詳しい条件'!C50+C8)))/10*5) | D43: ='② 詳しい条件'!C40*MAX(B9,1-(1-MIN(0.95,MAX(0.05,'② 詳しい条件'!C50+D8)))/10*5)
A44: 売却価格の目安 | B44: =B42+B43 | C44: =C42+C43 | D44: =D42+D43
A45: 売却の費用 | B45: =IF(B44<=2000000,B44*0.05,IF(B44<=4000000,B44*0.04+20000,B44*0.03+60000))*(1+B11)+B10 | C45: =IF(C44<=2000000,C44*0.05,IF(C44<=4000000,C44*0.04+20000,C44*0.03+60000))*(1+B11)+B10 | D45: =IF(D44<=2000000,D44*0.05,IF(D44<=4000000,D44*0.04+20000,D44*0.03+60000))*(1+B11)+B10 | E45: 仲介手数料（上限）＋その他
A46: ローン残高 | B46: =IF('② 詳しい条件'!B23=0,MAX(0,'③ 詳しい試算'!C14-'③ 詳しい試算'!C15*MIN(5*12,'② 詳しい条件'!B24*12)),MAX(0,'③ 詳しい試算'!C14*(1+'② 詳しい条件'!B23/12)^MIN(5*12,'② 詳しい条件'!B24*12)-'③ 詳しい試算'!C15*((1+'② 詳しい条件'!B23/12)^MIN(5*12,'② 詳しい条件'!B24*12)-1)/('② 詳しい条件'!B23/12))) | C46: =IF('② 詳しい条件'!B23=0,MAX(0,'③ 詳しい試算'!C14-'③ 詳しい試算'!C15*MIN(5*12,'② 詳しい条件'!B24*12)),MAX(0,'③ 詳しい試算'!C14*(1+'② 詳しい条件'!B23/12)^MIN(5*12,'② 詳しい条件'!B24*12)-'③ 詳しい試算'!C15*((1+'② 詳しい条件'!B23/12)^MIN(5*12,'② 詳しい条件'!B24*12)-1)/('② 詳しい条件'!B23/12))) | D46: =IF('② 詳しい条件'!B23=0,MAX(0,'③ 詳しい試算'!C14-'③ 詳しい試算'!C15*MIN(5*12,'② 詳しい条件'!B24*12)),MAX(0,'③ 詳しい試算'!C14*(1+'② 詳しい条件'!B23/12)^MIN(5*12,'② 詳しい条件'!B24*12)-'③ 詳しい試算'!C15*((1+'② 詳しい条件'!B23/12)^MIN(5*12,'② 詳しい条件'!B24*12)-1)/('② 詳しい条件'!B23/12)))
...

Sheet 参考：税額の概算
A1: 税額の概算（給与収入だけの単身者）
A2: 住宅ローン控除と「収入が減ったら」に使います。源泉徴収票がある場合は数字を見比べてください。
A5: 年収の変化
A6: 項目 | B6: 今の年収 | C6: 2割減 | D6: 4割減 | E6: メモ
A7: 年収の減り方 | B7: 0 | C7: 0.2 | D7: 0.4
A8: 年収 | B8: ='② 詳しい条件'!B7*(1-B7) | C8: ='② 詳しい条件'!B7*(1-C7) | D8: ='② 詳しい条件'!B7*(1-D7)
A9: 給与所得控除 | B9: =MIN(B8,MAX('参考：税の前提'!B13,B8*VLOOKUP(B8,'参考：税の前提'!$A$7:$C$12,2,TRUE)+VLOOKUP(B8,'参考：税の前提'!$A$7:$C$12,3,TRUE))) | C9: =MIN(C8,MAX('参考：税の前提'!B13,C8*VLOOKUP(C8,'参考：税の前提'!$A$7:$C$12,2,TRUE)+VLOOKUP(C8,'参考：税の前提'!$A$7:$C$12,3,TRUE))) | D9: =MIN(D8,MAX('参考：税の前提'!B13,D8*VLOOKUP(D8,'参考：税の前提'!$A$7:$C$12,2,TRUE)+VLOOKUP(D8,'参考：税の前提'!$A$7:$C$12,3,TRUE)))
A10: 合計所得金額 | B10: =MAX(0,B8-B9) | C10: =MAX(0,C8-C9) | D10: =MAX(0,D8-D9)
A11: 社会保険料 | B11: =B8*'② 詳しい条件'!B8 | C11: =C8*'② 詳しい条件'!B8 | D11: =D8*'② 詳しい条件'!B8
A12: 所得税の基礎控除 | B12: =VLOOKUP(B10,'参考：税の前提'!$A$17:$B$23,2,TRUE) | C12: =VLOOKUP(C10,'参考：税の前提'!$A$17:$B$23,2,TRUE) | D12: =VLOOKUP(D10,'参考：税の前提'!$A$17:$B$23,2,TRUE)
A13: 課税所得 | B13: =INT(MAX(0,B10-B11-B12)/1000)*1000 | C13: =INT(MAX(0,C10-C11-C12)/1000)*1000 | D13: =INT(MAX(0,D10-D11-D12)/1000)*1000
A14: 所得税（控除前） | B14: =MAX(0,INT(B13*VLOOKUP(B13,'参考：税の前提'!$A$28:$C$34,2,TRUE)-VLOOKUP(B13,'参考：税の前提'!$A$28:$C$34,3,TRUE))) | C14: =MAX(0,INT(C13*VLOOKUP(C13,'参考：税の前提'!$A$28:$C$34,2,TRUE)-VLOOKUP(C13,'参考：税の前提'!$A$28:$C$34,3,TRUE))) | D14: =MAX(0,INT(D13*VLOOKUP(D13,'参考：税の前提'!$A$28:$C$34,2,TRUE)-VLOOKUP(D13,'参考：税の前提'!$A$28:$C$34,3,TRUE)))
A15: 住民税の課税所得 | B15: =INT(MAX(0,B10-B11-'参考：税の前提'!B38)/1000)*1000 | C15: =INT(MAX(0,C10-C11-'参考：税の前提'!B38)/1000)*1000 | D15: =INT(MAX(0,D10-D11-'参考：税の前提'!B38)/1000)*1000
A16: 住民税（所得割） | B16: =MAX(0,INT(B15*'参考：税の前提'!B39-'参考：税の前提'!B40)) | C16: =MAX(0,INT(C15*'参考：税の前提'!B39-'参考：税の前提'!B40)) | D16: =MAX(0,INT(D15*'参考：税の前提'!B39-'参考：税の前提'!B40))
A17: 手取り（年額・概算） | B17: =B8-B11-B14*(1+'参考：税の前提'!B42)-B16-'参考：税の前提'!B41 | C17: =C8-C11-C14*(1+'参考：税の前提'!B42)-C16-'参考：税の前提'!B41 | D17: =D8-D11-D14*(1+'参考：税の前提'!B42)-D16-'参考：税の前提'!B41
A18: 手取り（月額・概算） | B18: =B17/12 | C18: =C17/12 | D18: =D17/12

Sheet 参考：税の前提
A1: 参考：税の前提
A2: 令和8・9年分の所得税の特例を2028年以降も続くと仮定（税額＝控除できる余地を低めに見積もる）。
A5: 給与所得控除（給与収入がこの額以上のとき：収入×率＋加算額）
A6: 給与収入（以上） | B6: 率 | C6: 加算額
A7: 0 | B7: 0 | C7: 550000
A8: 1625001 | B8: 0.4 | C8: -100000
A9: 1800001 | B9: 0.3 | C9: 80000
A10: 3600001 | B10: 0.2 | C10: 440000
A11: 6600001 | B11: 0.1 | C11: 1100000
A12: 8500001 | B12: 0 | C12: 1950000
A13: 給与所得控除の最低額 | B13: 740000 | D13: 令和8・9年分の特例（74万円）
A15: 所得税の基礎控除（合計所得金額がこの額を超えるとき）
A16: 合計所得（超） | B16: 基礎控除
A17: 0 | B17: 1040000
A18: 4890000 | B18: 670000
A19: 6550000 | B19: 620000
A20: 23500000 | B20: 480000
A21: 24000000 | B21: 320000
A22: 24500000 | B22: 160000
A23: 25000000 | B23: 0
A24: 「超える」を表すため、境目には0.001円を足しています（表示は円単位）。
A26: 所得税の税率（課税所得がこの額を超えるとき：課税所得×税率−控除額）
A27: 課税所得（以上） | B27: 税率 | C27: 控除額
A28: 0 | B28: 0.05 | C28: 0
A29: 1951000 | B29: 0.1 | C29: 97500
A30: 3301000 | B30: 0.2 | C30: 427500
A31: 6951000 | B31: 0.23 | C31: 636000
A32: 9001000 | B32: 0.33 | C32: 1536000
A33: 18001000 | B33: 0.4 | C33: 2796000
A34: 40001000 | B34: 0.45 | C34: 4796000
A36: その他の定数
A37: 項目 | B37: 値 | D37: メモ
A38: 住民税の基礎控除 | B38: 430000
A39: 住民税の所得割の税率 | B39: 0.1
A40: 住民税の調整控除（概算） | B40: 2500 | D40: 単身の概算
A41: 住民税の均等割など（年額） | B41: 5000 | D41: 手取りの概算に使う
A42: 復興特別所得税 | B42: 0.021 | D42: 所得税×2.1%

Sheet 参考：控除の制度
A1: 住宅ローン控除の制度（単身者・一般の借入限度額）
A2: 2026年10月時点。税制改正があったら、この表を書き換えます。
A5: 区分ごとの借入限度額と控除期間
A6: 区分 | B6: 省エネ性能 | C6: 入居年から | D6: 入居年まで | E6: 借入限度額 | F6: 控除期間（年） | G6: 建築確認の期限 | H6: 建築の期限 | I6: 注記
A7: 新築 | B7: 認定長期優良・低炭素 | C7: 2026 | D7: 2030 | E7: 45000000 | F7: 13
A8: 買取再販 | B8: 認定長期優良・低炭素 | C8: 2026 | D8: 2030 | E8: 45000000 | F8: 13 | I8: 買取再販の限度額は新築に準じる〔要確認〕
A9: 新築 | B9: ZEH水準省エネ | C9: 2026 | D9: 2030 | E9: 35000000 | F9: 13
A10: 買取再販 | B10: ZEH水準省エネ | C10: 2026 | D10: 2030 | E10: 35000000 | F10: 13 | I10: 買取再販の限度額は新築に準じる〔要確認〕
A11: 新築 | B11: 省エネ基準適合 | C11: 2026 | D11: 2027 | E11: 20000000 | F11: 13
A12: 買取再販 | B12: 省エネ基準適合 | C12: 2026 | D12: 2027 | E12: 20000000 | F12: 13 | I12: 買取再販の限度額は新築に準じる〔要確認〕
A13: 新築 | B13: 省エネ基準適合 | C13: 2028 | D13: 2030 | E13: 20000000 | F13: 10 | G13: 46752 | H13: 46934 | I13: 2028年以降の入居は、2027年末までに建築確認（または2028年6月末までに建築）したものに限り2,000万円・10年
A14: 買取再販 | B14: 省エネ基準適合 | C14: 2028 | D14: 2030 | E14: 20000000 | F14: 13 | I14: 買取再販の限度額は新築に準じる〔要確認〕
A15: 新築 | B15: その他 | C15: 2026 | D15: 2030 | E15: 20000000 | F15: 10 | G15: 45291 | H15: 45473 | I15: 省エネ基準を満たさない新築は、2023年末までに建築確認（または2024年6月末までに建築）したものに限り2,000万円・10年
A16: 買取再販 | B16: その他 | C16: 2026 | D16: 2030 | E16: 20000000 | F16: 10 | I16: 買取再販の限度額は新築に準じる〔要確認〕
A17: 中古 | B17: 認定長期優良・低炭素 | C17: 2026 | D17: 2030 | E17: 35000000 | F17: 13
A18: 中古 | B18: ZEH水準省エネ | C18: 2026 | D18: 2030 | E18: 35000000 | F18: 13
A19: 中古 | B19: 省エネ基準適合 | C19: 2026 | D19: 2030 | E19: 20000000 | F19: 13
A20: 中古 | B20: その他 | C20: 2026 | D20: 2030 | E20: 20000000 | F20: 10
A21: 建築確認の期限・建築の期限がある区分は、どちらかの期限までに満たしたものに限り対象。
A23: 共通の要件
A24: 項目 | B24: 値
A25: 控除率 | E25: 0.007
A26: 床面積の下限（㎡） | E26: 40
A27: この床面積未満は合計所得1,000万円以下の年だけ | E27: 50
A28: 床面積が小さい場合の合計所得の上限 | E28: 10000000
A29: 合計所得金額の上限 | E29: 20000000
A30: 返済期間の下限（年） | E30: 10
A31: 中古：この日以降の建築なら耐震の証明不要 | E31: 29952
A32: この入居年以降、レッドゾーンの新築は対象外 | E32: 2028
A33: 住民税から控除できる上限（課税総所得金額等に対する割合） | E33: 0.05
A34: 住民税から控除できる上限額〔要確認〕 | E34: 97500
